Workbook

Sheet How to Use
A1: Swasth Mann CMS - CRUD and Language Test Cases
A3: Every CRUD module (Add, View, Edit, Delete) works the same way, so each test case is written ONCE in the 'Test Cases' tab.
A4: 1. Open the 'Test Cases' tab and read the steps.
A5: 2. Go to the 'Test Matrix' tab. Each column is a module. Run each test case on each module and choose Pass, Fail, Blocked or N/A (if the feature does not exist in that module).
A6: 3. For every Fail, add a row in the 'Bug Log' tab with the Module, Test Case ID, what you saw and the expected result.
A7: 4. Check 'Module Details' for module-specific fields and linked modules.
A8: 5. The 'Summary' tab updates automatically.
A9: How to find where the bug is: a Fail in ONE column = bug in that module. A Fail across MANY columns in the same row (see Fail Count) = common bug in shared code.
A10: Language: run the LG test cases in both English and Nepali. Content missing in one language must fall back to the other.
A11: Authentication (login, lockout, rate limits, forgot password, session timeout) is tested in the separate 'Authentication' tab. Fill Actual Result and Status there. Limits and timings are noted in the 'Auth Settings' tab.

Sheet Summary
A1: Swasth Mann CMS - CRUD Test Summary
A3: Module | B3: Total | C3: Pass | D3: Fail | E3: Blocked | F3: N/A | G3: Not Run
A4: Screening Feedback | B4: =COUNTA('Test Matrix'!$A$2:$A$37) -> 35 | C4: =COUNTIF('Test Matrix'!D2:D37,"Pass") -> 25 | D4: =COUNTIF('Test Matrix'!D2:D37,"Fail") -> 6 | E4: =COUNTIF('Test Matrix'!D2:D37,"Blocked") -> 0 | F4: =COUNTIF('Test Matrix'!D2:D37,"N/A") -> 4 | G4: =B4-SUM(C4:F4) -> 0
A5: Suggestions | B5: =COUNTA('Test Matrix'!$A$2:$A$37) -> 35 | C5: =COUNTIF('Test Matrix'!E2:E37,"Pass") -> 27 | D5: =COUNTIF('Test Matrix'!E2:E37,"Fail") -> 5 | E5: =COUNTIF('Test Matrix'!E2:E37,"Blocked") -> 0 | F5: =COUNTIF('Test Matrix'!E2:E37,"N/A") -> 3 | G5: =B5-SUM(C5:F5) -> 0
A6: Questionnaires | B6: =COUNTA('Test Matrix'!$A$2:$A$37) -> 35 | C6: =COUNTIF('Test Matrix'!F2:F37,"Pass") -> 27 | D6: =COUNTIF('Test Matrix'!F2:F37,"Fail") -> 7 | E6: =COUNTIF('Test Matrix'!F2:F37,"Blocked") -> 0 | F6: =COUNTIF('Test Matrix'!F2:F37,"N/A") -> 1 | G6: =B6-SUM(C6:F6) -> 0
A7: Emergency Contacts | B7: =COUNTA('Test Matrix'!$A$2:$A$37) -> 35 | C7: =COUNTIF('Test Matrix'!G2:G37,"Pass") -> 28 | D7: =COUNTIF('Test Matrix'!G2:G37,"Fail") -> 2 | E7: =COUNTIF('Test Matrix'!G2:G37,"Blocked") -> 0 | F7: =COUNTIF('Test Matrix'!G2:G37,"N/A") -> 5 | G7: =B7-SUM(C7:F7) -> 0
A8: FAQs | B8: =COUNTA('Test Matrix'!$A$2:$A$37) -> 35 | C8: =COUNTIF('Test Matrix'!H2:H37,"Pass") -> 29 | D8: =COUNTIF('Test Matrix'!H2:H37,"Fail") -> 3 | E8: =COUNTIF('Test Matrix'!H2:H37,"Blocked") -> 0 | F8: =COUNTIF('Test Matrix'!H2:H37,"N/A") -> 3 | G8: =B8-SUM(C8:F8) -> 0
A9: Health Centers | B9: =COUNTA('Test Matrix'!$A$2:$A$37) -> 35 | C9: =COUNTIF('Test Matrix'!I2:I37,"Pass") -> 28 | D9: =COUNTIF('Test Matrix'!I2:I37,"Fail") -> 5 | E9: =COUNTIF('Test Matrix'!I2:I37,"Blocked") -> 0 | F9: =COUNTIF('Test Matrix'!I2:I37,"N/A") -> 2 | G9: =B9-SUM(C9:F9) -> 0
A10: Videos | B10: =COUNTA('Test Matrix'!$A$2:$A$37) -> 35 | C10: =COUNTIF('Test Matrix'!J2:J37,"Pass") -> 26 | D10: =COUNTIF('Test Matrix'!J2:J37,"Fail") -> 6 | E10: =COUNTIF('Test Matrix'!J2:J37,"Blocked") -> 0 | F10: =COUNTIF('Test Matrix'!J2:J37,"N/A") -> 3 | G10: =B10-SUM(C10:F10) -> 0
A11: About Us | B11: =COUNTA('Test Matrix'!$A$2:$A$37) -> 35 | C11: =COUNTIF('Test Matrix'!K2:K37,"Pass") -> 24 | D11: =COUNTIF('Test Matrix'!K2:K37,"Fail") -> 5 | E11: =COUNTIF('Test Matrix'!K2:K37,"Blocked") -> 0 | F11: =COUNTIF('Test Matrix'!K2:K37,"N/A") -> 6 | G11: =B11-SUM(C11:F11) -> 0
A12: Testimonials | B12: =COUNTA('Test Matrix'!$A$2:$A$37) -> 35 | C12: =COUNTIF('Test Matrix'!L2:L37,"Pass") -> 24 | D12: =COUNTIF('Test Matrix'!L2:L37,"Fail") -> 8 | E12: =COUNTIF('Test Matrix'!L2:L37,"Blocked") -> 0 | F12: =COUNTIF('Test Matrix'!L2:L37,"N/A") -> 3 | G12: =B12-SUM(C12:F12) -> 0
A13: Self Care | B13: =COUNTA('Test Matrix'!$A$2:$A$37) -> 35 | C13: =COUNTIF('Test Matrix'!M2:M37,"Pass") -> 25 | D13: =COUNTIF('Test Matrix'!M2:M37,"Fail") -> 5 | E13: =COUNTIF('Test Matrix'!M2:M37,"Blocked") -> 0 | F13: =COUNTIF('Test Matrix'!M2:M37,"N/A") -> 4 | G13: =B13-SUM(C13:F13) -> 1
A14: Video Categories | B14: =COUNTA('Test Matrix'!$A$2:$A$37) -> 35 | C14: =COUNTIF('Test Matrix'!N2:N37,"Pass") -> 25 | D14: =COUNTIF('Test Matrix'!N2:N37,"Fail") -> 6 | E14: =COUNTIF('Test Matrix'!N2:N37,"Blocked") -> 0 | F14: =COUNTIF('Test Matrix'!N2:N37,"N/A") -> 4 | G14: =B14-SUM(C14:F14) -> 0
A15: Other Resources | B15: =COUNTA('Test Matrix'!$A$2:$A$37) -> 35 | C15: =COUNTIF('Test Matrix'!O2:O37,"Pass") -> 25 | D15: =COUNTIF('Test Matrix'!O2:O37,"Fail") -> 5 | E15: =COUNTIF('Test Matrix'!O2:O37,"Blocked") -> 0 | F15: =COUNTIF('Test Matrix'!O2:O37,"N/A") -> 5 | G15: =B15-SUM(C15:F15) -> 0
A16: Resource Categories | B16: =COUNTA('Test Matrix'!$A$2:$A$37) -> 35 | C16: =COUNTIF('Test Matrix'!P2:P37,"Pass") -> 27 | D16: =COUNTIF('Test Matrix'!P2:P37,"Fail") -> 3 | E16: =COUNTIF('Test Matrix'!P2:P37,"Blocked") -> 0 | F16: =COUNTIF('Test Matrix'!P2:P37,"N/A") -> 5 | G16: =B16-SUM(C16:F16) -> 0
A17: Events | B17: =COUNTA('Test Matrix'!$A$2:$A$37) -> 35 | C17: =COUNTIF('Test Matrix'!Q2:Q37,"Pass") -> 27 | D17: =COUNTIF('Test Matrix'!Q2:Q37,"Fail") -> 5 | E17: =COUNTIF('Test Matrix'!Q2:Q37,"Blocked") -> 0 | F17: =COUNTIF('Test Matrix'!Q2:Q37,"N/A") -> 3 | G17: =B17-SUM(C17:F17) -> 0
A18: About Us Categories | B18: =COUNTA('Test Matrix'!$A$2:$A$37) -> 35 | C18: =COUNTIF('Test Matrix'!R2:R37,"Pass") -> 1 | D18: =COUNTIF('Test Matrix'!R2:R37,"Fail") -> 1 | E18: =COUNTIF('Test Matrix'!R2:R37,"Blocked") -> 0 | F18: =COUNTIF('Test Matrix'!R2:R37,"N/A") -> 0 | G18: =B18-SUM(C18:F18) -> 33
A19: Option Groups | B19: =COUNTA('Test Matrix'!$A$2:$A$37) -> 35 | C19: =COUNTIF('Test Matrix'!S2:S37,"Pass") -> 0 | D19: =COUNTIF('Test Matrix'!S2:S37,"Fail") -> 0 | E19: =COUNTIF('Test Matrix'!S2:S37,"Blocked") -> 0 | F19: =COUNTIF('Test Matrix'!S2:S37,"N/A") -> 0 | G19: =B19-SUM(C19:F19) -> 35
A20: Question Types | B20: =COUNTA('Test Matrix'!$A$2:$A$37) -> 35 | C20: =COUNTIF('Test Matrix'!T2:T37,"Pass") -> 0 | D20: =COUNTIF('Test Matrix'!T2:T37,"Fail") -> 0 | E20: =COUNTIF('Test Matrix'!T2:T37,"Blocked") -> 0 | F20: =COUNTIF('Test Matrix'!T2:T37,"N/A") -> 0 | G20: =B20-SUM(C20:F20) -> 35
A21: Suggestion Categories | B21: =COUNTA('Test Matrix'!$A$2:$A$37) -> 35 | C21: =COUNTIF('Test Matrix'!U2:U37,"Pass") -> 0 | D21: =COUNTIF('Test Matrix'!U2:U37,"Fail") -> 0 | E21: =COUNTIF('Test Matrix'!U2:U37,"Blocked") -> 0 | F21: =COUNTIF('Test Matrix'!U2:U37,"N/A") -> 0 | G21: =B21-SUM(C21:F21) -> 35
A22: Health Center Categories | B22: =COUNTA('Test Matrix'!$A$2:$A$37) -> 35 | C22: =COUNTIF('Test Matrix'!V2:V37,"Pass") -> 0 | D22: =COUNTIF('Test Matrix'!V2:V37,"Fail") -> 0 | E22: =COUNTIF('Test Matrix'!V2:V37,"Blocked") -> 0 | F22: =COUNTIF('Test Matrix'!V2:V37,"N/A") -> 0 | G22: =B22-SUM(C22:F22) -> 35
A23: Health Center Services | B23: =COUNTA('Test Matrix'!$A$2:$A$37) -> 35 | C23: =COUNTIF('Test Matrix'!W2:W37,"Pass") -> 0 | D23: =COUNTIF('Test Matrix'!W2:W37,"Fail") -> 0 | E23: =COUNTIF('Test Matrix'!W2:W37,"Blocked") -> 0 | F23: =COUNTIF('Test Matrix'!W2:W37,"N/A") -> 0 | G23: =B23-SUM(C23:F23) -> 35
A24: Health Center Specialists | B24: =COUNTA('Test Matrix'!$A$2:$A$37) -> 35 | C24: =COUNTIF('Test Matrix'!X2:X37,"Pass") -> 0 | D24: =COUNTIF('Test Matrix'!X2:X37,"Fail") -> 0 | E24: =COUNTIF('Test Matrix'!X2:X37,"Blocked") -> 0 | F24: =COUNTIF('Test Matrix'!X2:X37,"N/A") -> 0 | G24: =B24-SUM(C24:F24) -> 35
A25: Health Center Departments | B25: =COUNTA('Test Matrix'!$A$2:$A$37) -> 35 | C25: =COUNTIF('Test Matrix'!Y2:Y37,"Pass") -> 0 | D25: =COUNTIF('Test Matrix'!Y2:Y37,"Fail") -> 0 | E25: =COUNTIF('Test Matrix'!Y2:Y37,"Blocked") -> 0 | F25: =COUNTIF('Test Matrix'!Y2:Y37,"N/A") -> 0 | G25: =B25-SUM(C25:F25) -> 35
A26: Schools | B26: =COUNTA('Test Matrix'!$A$2:$A$37) -> 35 | C26: =COUNTIF('Test Matrix'!Z2:Z37,"Pass") -> 0 | D26: =COUNTIF('Test Matrix'!Z2:Z37,"Fail") -> 0 | E26: =COUNTIF('Test Matrix'!Z2:Z37,"Blocked") -> 0 | F26: =COUNTIF('Test Matrix'!Z2:Z37,"N/A") -> 0 | G26: =B26-SUM(C26:F26) -> 35
A27: States | B27: =COUNTA('Test Matrix'!$A$2:$A$37) -> 35 | C27: =COUNTIF('Test Matrix'!AA2:AA37,"Pass") -> 0 | D27: =COUNTIF('Test Matrix'!AA2:AA37,"Fail") -> 0 | E27: =COUNTIF('Test Matrix'!AA2:AA37,"Blocked") -> 0 | F27: =COUNTIF('Test Matrix'!AA2:AA37,"N/A") -> 0 | G27: =B27-SUM(C27:F27) -> 35
A28: Districts | B28: =COUNTA('Test Matrix'!$A$2:$A$37) -> 35 | C28: =COUNTIF('Test Matrix'!AB2:AB37,"Pass") -> 0 | D28: =COUNTIF('Test Matrix'!AB2:AB37,"Fail") -> 0 | E28: =COUNTIF('Test Matrix'!AB2:AB37,"Blocked") -> 0 | F28: =COUNTIF('Test Matrix'!AB2:AB37,"N/A") -> 0 | G28: =B28-SUM(C28:F28) -> 35
A29: Total | B29: =SUM(B4:B28) -> 875 | C29: =SUM(C4:C28) -> 368 | D29: =SUM(D4:D28) -> 72 | E29: =SUM(E4:E28) -> 0 | F29: =SUM(F4:F28) -> 51 | G29: =SUM(G4:G28) -> 384
A31: Authentication (separate tab) | B31: =COUNTA(Authentication!$A$2:$A$50) -> 49 | C31: =COUNTIF(Authentication!$H$2:$H$50,"Pass") -> 37 | D31: =COUNTIF(Authentication!$H$2:$H$50,"Fail") -> 3 | E31: =COUNTIF(Authentication!$H$2:$H$50,"Blocked") -> 0 | F31: - | G31: =B31-C31-D31-E31 -> 9

Sheet Test Cases
A1: Test Case ID | B1: Area | C1: Scenario | D1: Precondition | E1: Steps | F1: Expected Result | G1: Applies To
A2: CR-01 | B2: List | C2: Open module page | D2: Logged in | E2: 1. Click the module in the sidebar | F2: Page opens with the correct title, list and Add button. Sidebar item is highlighted | G2: All
A3: CR-02 | B3: List | C3: List shows correct data | D3: Records exist | E3: 1. Check number, title and date of each card | F3: Data is correct and complete. Default sort order is consistent | G3: All
A4: CR-03 | B4: List | C4: Search | D4: Records exist | E4: 1. Type a word in the search box | F4: Only matching records are shown | G4: All
A5: CR-04 | B5: List | C5: Search with no match | D5: Module page is open | E5: 1. Type text that does not exist | F5: 'No records found' message is shown | G5: All
A6: CR-05 | B6: List | C6: Grid and list view toggle | D6: Module page is open | E6: 1. Click list icon 2. Click grid icon | F6: Layout changes and the same records are shown | G6: All
A7: CR-06 | B7: List | C7: Pagination and page size | D7: More than 10 records | E7: 1. Click Next, Previous, First, Last 2. Change Page Size | F7: 'Showing 1-10 of N' and page count are correct and all buttons work | G7: All
A8: CR-07 | B8: List | C8: Empty state | D8: Module with no records | E8: 1. Open the module | F8: Empty message is shown with no broken layout | G8: All
A9: CR-08 | B9: Create | C9: Open Add form | D9: Module page is open | E9: 1. Click the Add button | F9: Add form opens with all fields and the correct title | G9: All
A10: CR-09 | B10: Create | C10: Add with valid data | D10: Add form is open | E10: 1. Fill all fields with valid data 2. Click Save | F10: Record is saved, form closes, success message shown and the record appears in the list | G10: All
A11: CR-10 | B11: Create | C11: Required field validation | D11: Add form is open | E11: 1. Leave required fields empty 2. Click Save | F11: Error message shows for each required field and nothing is saved. Errors should appear only after Save | G11: All
A12: CR-11 | B12: Create | C12: Cancel or close Add form | D12: Add form is open | E12: 1. Enter some data 2. Click Cancel 3. Reopen and click X | F12: Form closes and no record is added | G12: All
... A36: LG-11 | B36: Language | C36: Language stays after Save and refresh | D36: Nepali selected | E36: 1. Save a record 2. Refresh the page | F36: Selected language stays and content shows correctly | G36: All

Sheet Test Matrix
A1: Test Case ID | B1: Scenario | C1: Fail Count | D1: Screening Feedback | E1: Suggestions | F1: Questionnaires | G1: Emergency Contacts | H1: FAQs | I1: Health Centers | J1: Videos | K1: About Us | L1: Testimonials | M1: Self Care | N1: Video Categories | O1: Other Resources | P1: Resource Categories | Q1: Events | R1: About Us Categories | S1: Option Groups | T1: Question Types | U1: Suggestion Categories | V1: Health Center Categories | W1: Health Center Services | X1: Health Center Specialists | Y1: Health Center Departments | Z1: Schools | AA1: States | AB1: Districts
A2: CR-01 | B2: Open module page | C2: =COUNTIF(D2:AB2,"Fail") -> 1 | D2: pass | E2: pass | F2: pass | G2: pass | H2: pass | I2: pass | J2: pass | K2: fail | L2: pass | M2: pass | N2: pass | O2: pass | P2: pass | Q2: pass | R2: pass
A3: CR-02 | B3: List shows correct data | C3: =COUNTIF(D3:AB3,"Fail") -> 6 | D3: Fail | E3: fail | F3: fail | G3: pass | H3: pass | I3: pass | J3: pass | K3: fail | L3: Pass | M3: fail | N3: pass | O3: pass | P3: pass | Q3: pass | R3: fail
A4: CR-03 | B4: Search | C4: =COUNTIF(D4:AB4,"Fail") -> 6 | D4: Fail | E4: fail | F4: fail | G4: pass | H4: pass | I4: pass | J4: fail | K4: fail | L4: Pass | M4: pass | N4: pass | O4: fail | P4: pass | Q4: pass
A5: CR-04 | B5: Search with no match | C5: =COUNTIF(D5:AB5,"Fail") -> 0 | D5: pass | E5: pass | F5: pass | G5: pass | H5: pass | I5: pass | J5: pass | K5: pass | L5: pass | M5: pass | N5: pass | O5: pass | P5: pass | Q5: pass
A6: CR-05 | B6: Grid and list view toggle | C6: =COUNTIF(D6:AB6,"Fail") -> 0 | D6: pass | E6: Pass | F6: pass | G6: pass | H6: pass | I6: pass | J6: pass | K6: pass | L6: pass | M6: pass | N6: pass | O6: pass | P6: pass | Q6: pass
A7: CR-06 | B7: Pagination and page size | C7: =COUNTIF(D7:AB7,"Fail") -> 2 | D7: fail | E7: pass | F7: pass | G7: n/a | H7: pass | I7: pass | J7: pass | K7: n/a | L7: N/A | M7: fail | N7: n/a | O7: n/a | P7: n/a | Q7: pass
A8: CR-07 | B8: Empty state | C8: =COUNTIF(D8:AB8,"Fail") -> 0 | D8: N/A | E8: pass | F8: pass | G8: n/a | H8: pass | I8: N/A | J8: pass | K8: n/a | L8: N/A | M8: n/a | N8: n/a | O8: n/a | P8: n/a | Q8: pass
A9: CR-08 | B9: Open Add form | C9: =COUNTIF(D9:AB9,"Fail") -> 0 | D9: pass | E9: pass | F9: pass | G9: pass | H9: pass | I9: pass | J9: pass | K9: pass | L9: pass | M9: pass | N9: pass | O9: pass | P9: pass | Q9: pass
A10: CR-09 | B10: Add with valid data | C10: =COUNTIF(D10:AB10,"Fail") -> 1 | D10: pass | E10: pass | F10: pass | G10: pass | H10: pass | I10: pass | J10: pass | K10: Pass | L10: Fail | M10: pass | N10: pass | O10: pass | P10: pass | Q10: pass
A11: CR-10 | B11: Required field validation | C11: =COUNTIF(D11:AB11,"Fail") -> 4 | D11: pass | E11: pass | F11: fail | G11: pass | H11: pass | I11: pass | J11: pass | K11: pass | L11: pass | M11: fail | N11: pass | O11: pass | P11: fail | Q11: fail
A12: CR-11 | B12: Cancel or close Add form | C12: =COUNTIF(D12:AB12,"Fail") -> 1 | D12: pass | E12: pass | F12: pass | G12: pass | H12: pass | I12: pass | J12: pass | K12: pass | L12: fail | M12: pass | N12: pass | O12: pass | P12: pass | Q12: pass
A13: CR-12 | B13: Duplicate entry | C13: =COUNTIF(D13:AB13,"Fail") -> 7 | D13: fail | E13: pass | F13: fail | G13: pass | H13: pass | I13: pass | J13: fail | K13: fail | L13: fail | M13: pass | N13: pass | O13: fail | P13: pass | Q13: fail
A14: CR-13 | B14: Dropdown fields load | C14: =COUNTIF(D14:AB14,"Fail") -> 2 | D14: pass | E14: N/A | F14: fail | G14: n/a | H14: n/a | I14: pass | J14: n/a | K14: n/a | L14: pass | M14: n/a | N14: pass | O14: pass | P14: n/a | Q14: fail
A15: CR-14 | B15: File or image upload | C15: =COUNTIF(D15:AB15,"Fail") -> 0 | D15: N/A | E15: N/A | F15: n/a | G15: n/a | H15: n/a | I15: N/A | J15: n/a | K15: n/a | L15: pass | M15: n/a | N15: n/a | O15: n/a | P15: n/a | Q15: n/a
... A24: CR-23 | B24: Delete a record linked to another module | C24: =COUNTIF(D24:AB24,"Fail") -> 0 | D24: N/A | E24: N/A | F24: pass | G24: n/a | H24: n/a | I24: pass | J24: n/a | K24: n/a | L24: N/A | M24: n/a | N24: pass | O24: n/a | P24: pass | Q24: n/a
A25: CR-24 | B25: Change reflects in the app | C25: =COUNTIF(D25:AB25,"Fail") -> 2 | D25: N/A | E25: pass | F25: pass | G25: pass | H25: fail | I25: pass | J25: fail | K25: pass | L25: pass | N25: pass | O25: n/a | P25: n/a | Q25: n/a
A27: LG-01 | B27: Switch language from top bar | C27: =COUNTIF(D27:AB27,"Fail") -> 9 | D27: fail | E27: Fail | F27: fail | G27: pass | H27: pass | I27: fail | J27: fail | K27: pass | L27: pass | M27: pass | N27: fail | O27: fail | P27: fail | Q27: fail
A28: LG-02 | B28: Add in English only | C28: =COUNTIF(D28:AB28,"Fail") -> 3 | D28: pass | E28: Pass | F28: pass | G28: pass | H28: pass | I28: fail | J28: pass | K28: pass | L28: fail | M28: pass | N28: fail | O28: pass | P28: pass | Q28: pass
A29: LG-03 | B29: Add Nepali content to an existing record | C29: =COUNTIF(D29:AB29,"Fail") -> 1 | D29: pass | E29: pass | F29: pass | G29: pass | H29: pass | I29: pass | J29: pass | K29: pass | L29: pass | M29: pass | N29: fail | O29: pass | P29: pass | Q29: pass
A30: LG-04 | B30: Nepali-only record | C30: =COUNTIF(D30:AB30,"Fail") -> 2 | D30: pass | E30: pass | F30: pass | G30: pass | H30: pass | I30: fail | J30: pass | K30: pass | L30: pass | M30: pass | N30: fail | O30: pass | P30: pass | Q30: pass
A31: LG-05 | B31: Edit does not affect the other language | C31: =COUNTIF(D31:AB31,"Fail") -> 2 | D31: pass | E31: pass | F31: pass | G31: pass | H31: pass | I31: fail | J31: pass | K31: pass | L31: pass | M31: pass | N31: fail | O31: pass | P31: pass | Q31: pass
A32: LG-06 | B32: Language badge in Add and Edit form | C32: =COUNTIF(D32:AB32,"Fail") -> 0 | D32: pass | E32: pass | F32: pass | G32: pass | H32: pass | I32: pass | J32: pass | K32: pass | L32: pass | M32: pass | N32: pass | O32: pass | P32: pass | Q32: pass
A33: LG-07 | B33: Nepali text saves and displays correctly | C33: =COUNTIF(D33:AB33,"Fail") -> 4 | D33: pass | E33: pass | F33: pass | G33: pass | H33: fail | I33: fail | J33: fail | K33: pass | L33: pass | M33: pass | N33: fail | O33: pass | P33: pass | Q33: pass
A34: LG-08 | B34: Search in each language | C34: =COUNTIF(D34:AB34,"Fail") -> 5 | D34: pass | E34: fail | F34: pass | G34: fail | H34: pass | I34: pass | J34: pass | K34: pass | L34: fail | M34: fail | N34: pass | O34: fail | P34: pass | Q34: pass
A35: LG-09 | B35: Delete removes both language versions | C35: =COUNTIF(D35:AB35,"Fail") -> 12 | D35: fail | E35: fail | F35: fail | G35: fail | H35: fail | I35: pass | J35: fail | K35: fail | L35: fail | M35: fail | N35: pass | O35: fail | P35: fail | Q35: fail
A36: LG-10 | B36: Dropdown values in selected language | C36: =COUNTIF(D36:AB36,"Fail") -> 0 | D36: pass | E36: pass | F36: pass | G36: pass | H36: pass | I36: pass | J36: pass | K36: n/a | L36: pass | M36: pass | N36: N/A | O36: pass | P36: pass | Q36: pass
A37: LG-11 | B37: Language stays after Save and refresh | C37: =COUNTIF(D37:AB37,"Fail") -> 1 | D37: pass | E37: pass | F37: pass | G37: pass | H37: pass | I37: pass | J37: pass | K37: pass | L37: fail | M37: pass | N37: pass | O37: pass | P37: pass | Q37: pass

Sheet Module Details
A1: Module | B1: Group | C1: Module-specific fields to check | D1: Linked module to check | E1: Remarks
A2: Screening Feedback | B2: Main | C2: Feedback text, date, rating (if any) | D2: Screening Reports | E2: Mark N/A where the feature is view-only
A3: Suggestions | B3: Main | C3: Suggestion text, category, date | D3: Suggestion Categories
A4: Questionnaires | B4: Main | C4: Questions, answer options, scores, question type | D4: Option Groups, Question Types | E4: Score change must show correct risk level in Reports
A5: Emergency Contacts | B5: Main | C5: Name, phone number format
A6: FAQs | B6: Main | C6: Question, answer (rich text) | E6: Edit form title must say FAQ
A7: Health Centers | B7: Main | C7: Name, address, phone, state, district, category, services, specialists, departments | D7: States, Districts, all Health Center masters | E7: Most linked module
A8: Videos | B8: Main | C8: Title, video link, thumbnail, category | D8: Video Categories | E8: Link must open the video
A9: About Us | B9: Main | C9: Title, content, category | D9: About Us Categories
A10: Testimonials | B10: Configure | C10: Name, message, photo
A11: Self Care | B11: Configure | C11: Title, content, image
A12: Video Categories | B12: Configure | C12: Category name | D12: Videos | E12: Deleting a category in use
A13: Other Resources | B13: Configure | C13: Title, file or link, category | D13: Resource Categories | E13: File must open or download
A14: Resource Categories | B14: Configure | C14: Category name | D14: Other Resources | E14: Deleting a category in use
A15: Events | B15: Configure | C15: Title, date and time, venue, description | E15: Past and future date handling
A16: About Us Categories | B16: Configure | C16: Category name | D16: About Us | E16: Deleting a category in use
A17: Option Groups | B17: Configure | C17: Option names, score values | D17: Questionnaires | E17: Editing must not break old screenings
A18: Question Types | B18: Configure | C18: Type name | D18: Questionnaires
A19: Suggestion Categories | B19: Configure | C19: Category name | D19: Suggestions | E19: Deleting a category in use
A20: Health Center Categories | B20: Configure | C20: Category name | D20: Health Centers | E20: Deleting a category in use
A21: Health Center Services | B21: Configure | C21: Service name | D21: Health Centers | E21: Deleting a service in use
A22: Health Center Specialists | B22: Configure | C22: Specialist name | D22: Health Centers | E22: Deleting a specialist in use
A23: Health Center Departments | B23: Configure | C23: Department name | D23: Health Centers | E23: Deleting a department in use
A24: Schools | B24: Configure | C24: School name, state, district | D24: States, Districts | E24: Used in school screenings
A25: States | B25: Configure | C25: State name | D25: Districts, Health Centers, Schools | E25: Deleting a state with districts
A26: Districts | B26: Configure | C26: District name, state | D26: States, Health Centers, Schools | E26: Must match the selected state
A27: Authentication | B27: Auth | C27: Login, lockout, rate limits, forgot password, session timeout | D27: Manage Users | E27: See Auth Settings tab

Sheet Authentication
A1: Test Case ID | B1: Module | C1: Scenario | D1: Precondition | E1: Steps | F1: Expected Result | G1: Actual Result | H1: Status | I1: Remarks
A2: AU-01 | B2: Auth - Login | C2: Login page loads | D2: Not logged in | E2: 1. Open the admin panel URL | F2: Page shows 'Login to Account', Username, Password (masked), 'Forgot password?' link and Sign In button | G2: as expected | H2: Pass
A3: AU-02 | B3: Auth - Login | C3: Valid login | D3: Active user exists | E3: 1. Enter valid username (phone number) and password 2. Click Sign In | F3: User lands on the Dashboard. Repeat for each role (SuperAdmin, Admin, etc.) | G3: as expected | H3: Pass
A4: AU-03 | B4: Auth - Login | C4: Wrong password | D4: Active user exists | E4: 1. Enter valid username and a wrong password 2. Click Sign In | F4: Error message is shown and the user stays on the login page | G4: as expected | H4: Pass
A5: AU-04 | B5: Auth - Login | C5: Unregistered username | D5: None | E5: 1. Enter a phone number that is not registered 2. Click Sign In | F5: Error message is shown. It does not reveal whether the username or the password was wrong | G5: as expected | H5: pass
A6: AU-05 | B6: Auth - Login | C6: Empty fields | D6: None | E6: 1. Leave username and password empty 2. Click Sign In | F6: Required-field messages are shown and login does not happen | G6: as expected | H6: pass
A7: AU-06 | B7: Auth - Login | C7: Disabled user | D7: Disabled user exists (Manage Users) | E7: 1. Enter the correct credentials of a disabled user | F7: Login is blocked with a clear message | G7: as expected | H7: pass
A8: AU-07 | B8: Auth - Login | C8: Menus after login by role | D8: Users of different roles exist | E8: 1. Log in with each role | F8: Each role sees only the menus it is allowed to use | G8: as expected | H8: Pass
A9: AU-08 | B9: Auth - Login | C9: Open login page while logged in | D9: Logged in | E9: 1. Open the login URL in the same browser | F9: User is redirected to the Dashboard | G9: as expected | H9: pass
A10: AU-09 | B10: Auth - Lockout and Rate Limit | C10: Account lock after wrong attempts | D10: Active user. Note allowed attempts (N) in Auth Settings | E10: 1. Enter a wrong password N times | F10: After N failed attempts: 'Account is temporarily locked due to multiple failed login attempts. Try again in 10 minute(s).' | G10: as expected | H10: pass | I10: locked for 30 minutes
A11: AU-10 | B11: Auth - Lockout and Rate Limit | C11: Correct password while locked | D11: Account is locked | E11: 1. Enter the correct password | F11: Login is still blocked and the lock message is shown | G11: as expected | H11: pass
A12: AU-11 | B12: Auth - Lockout and Rate Limit | C12: Lock countdown | D12: Account is locked | E12: 1. Wait 5 minutes 2. Try to log in again | F12: Message shows the remaining time (about 5 minute(s)), not always 10 | G12: as expected | H12: pass
A13: AU-12 | B13: Auth - Lockout and Rate Limit | C13: Login after lock time ends | D13: Lock time (10 minutes) has passed | E13: 1. Log in with the correct password | F13: Login works | G13: as expected | H13: pass
A14: AU-13 | B14: Auth - Lockout and Rate Limit | C14: Wrong-attempt counter resets after successful login | D14: Active user | E14: 1. Enter a wrong password N-1 times 2. Log in correctly 3. Log out 4. Enter a wrong password once | F14: Account is not locked and the count starts again from 1 | G14: as expected | H14: pass
A15: AU-14 | B15: Auth - Lockout and Rate Limit | C15: Lock applies only to that account | D15: One account is locked | E15: 1. Log in with another account | F15: The other account logs in normally | G15: as expected | H15: pass
A16: AU-15 | B16: Auth - Lockout and Rate Limit | C16: Lock cannot be bypassed | D16: Account is locked | E16: 1. Refresh the page 2. Try in another browser or incognito | F16: Account is still locked | G16: as expected | H16: pass
A17: AU-16 | B17: Auth - Lockout and Rate Limit | C17: Login rate limit is hit | D17: Login page is open | E17: 1. Submit login requests many times quickly (also with different usernames) | F17: After the limit, a rate-limit message is shown and login is blocked for a while. Note the limit in Auth Settings | G17: as expected | H17: Not Run
A18: AU-17 | B18: Auth - Lockout and Rate Limit | C18: Login rate limit lifts | D18: Login rate limit is hit | E18: 1. Wait for the time stated 2. Log in | F18: Login works again | G18: as expected | H18: Not Run
A19: AU-18 | B19: Auth - Forgot Password | C19: Open Forgot Password | D19: Login page is open | E19: 1. Click 'Forgot password?' | F19: Page shows Phone Number field, Send OTP and Back buttons | G19: as expected | H19: pass
A20: AU-19 | B20: Auth - Forgot Password | C20: Send OTP to a registered number | D20: Active user exists | E20: 1. Enter the registered phone number 2. Click Send OTP | F20: A 6-digit OTP is received and the 'Set A New Password' page opens | G20: as expected | H20: pass
A21: AU-20 | B21: Auth - Forgot Password | C21: Empty phone number | D21: Forgot Password page is open | E21: 1. Leave the phone number empty 2. Click Send OTP | F21: Required message is shown and no OTP is sent | G21: as expected | H21: pass
A22: AU-21 | B22: Auth - Forgot Password | C22: Invalid phone number | D22: Forgot Password page is open | E22: 1. Enter letters or a wrong-length number 2. Click Send OTP | F22: Error message is shown and no OTP is sent | G22: as expected | H22: pass
A23: AU-22 | B23: Auth - Forgot Password | C23: Unregistered or disabled number | D23: Forgot Password page is open | E23: 1. Enter an unregistered number 2. Enter a disabled user's number | F23: OTP is not sent, and a clear or generic message is shown with no system error | G23: as expected | H23: pass
A24: AU-23 | B24: Auth - Forgot Password | C24: OTP request rate limit is hit | D24: Forgot Password page is open | E24: 1. Click Send OTP again and again until the limit is reached | F24: 'Too many requests right now - please try again in a little while.' is shown and no more OTPs are sent. Note the limit in Auth Settings | G24: as expected | H24: fail | I24: otp sent and a message the next can be sent in 60 seconds
A25: AU-24 | B25: Auth - Forgot Password | C25: OTP rate limit lifts | D25: OTP rate limit is hit | E25: 1. Wait for the block time 2. Click Send OTP | F25: OTP is sent again | G25: as expected | H25: n/a
A26: AU-25 | B26: Auth - Forgot Password | C26: Back button on Forgot Password | D26: Forgot Password page is open | E26: 1. Click Back | F26: User returns to the login page | G26: as expected | H26: pass
A27: AU-26 | B27: Auth - Forgot Password | C27: Reset password on a locked account | D27: Account is locked | E27: 1. Reset the password using OTP 2. Try to log in | F27: Behaviour is as designed (stays locked or gets unlocked). Note what happens | G27: as expected | H27: pass | I27: does not allow to send otp and shows disabled by admin msg
A28: AU-27 | B28: Auth - Set New Password | C28: Page elements and resend timer | D28: OTP is sent | E28: 1. Check the page | F28: OTP Code, New Password (min 6 characters), Confirm Password, Reset Password and Back are shown, and the Resend countdown (e.g. 58s) is running | G28: as expected | H28: pass
A29: AU-28 | B29: Auth - Set New Password | C29: Resend OTP | D29: Set New Password page is open | E29: 1. Try Resend while the timer runs 2. Wait until it ends and click Resend | F29: Resend is disabled while the timer runs. After it ends, a new OTP is sent and the timer restarts | G29: as expected | H29: pass
A30: AU-29 | B30: Auth - Set New Password | C30: Old OTP after resend | D30: OTP was resent | E30: 1. Enter the first (old) OTP 2. Enter the new OTP | F30: Old OTP is rejected and the new OTP works | G30: as expected | H30: pass
A31: AU-30 | B31: Auth - Set New Password | C31: Valid password reset | D31: Valid OTP received | E31: 1. Enter OTP, new password and the same confirm password 2. Click Reset Password 3. Log in with the new password | F31: Success message, user goes to login, the new password works and the old password does not | G31: as expected | H31: pass
A32: AU-31 | B32: Auth - Set New Password | C32: Wrong OTP | D32: Set New Password page is open | E32: 1. Enter a wrong OTP 2. Click Reset Password | F32: Error message is shown and the password is not changed | G32: as expected | H32: pass
A33: AU-32 | B33: Auth - Set New Password | C33: Expired OTP | D33: OTP is older than its validity time | E33: 1. Wait beyond the OTP validity 2. Enter the OTP | F33: 'OTP expired' or similar message is shown and the password is not changed | G33: as expected | H33: Not Run
A34: AU-33 | B34: Auth - Set New Password | C34: Wrong OTP attempts limit | D34: Set New Password page is open | E34: 1. Enter a wrong OTP again and again | F34: After the limit, more attempts are blocked or a new OTP is required | G34: as expected | H34: fail | I34: no block message
A35: AU-34 | B35: Auth - Set New Password | C35: OTP field accepts 6 digits only | D35: Set New Password page is open | E35: 1. Type letters, symbols and more than 6 digits | F35: Only 6 digits are accepted | G35: as expected | H35: pass
A36: AU-35 | B36: Auth - Set New Password | C36: Password shorter than 6 characters | D36: Set New Password page is open | E36: 1. Enter a valid OTP and a 5-character password 2. Click Reset Password | F36: Error message is shown and the password is not changed | G36: as expected | H36: pass
A37: AU-36 | B37: Auth - Set New Password | C37: Password and Confirm Password do not match | D37: Set New Password page is open | E37: 1. Enter different values 2. Click Reset Password | F37: Error message is shown and the password is not changed | G37: as expected | H37: pass
A38: AU-37 | B38: Auth - Set New Password | C38: Empty fields | D38: Set New Password page is open | E38: 1. Leave all fields empty 2. Click Reset Password | F38: Required-field messages are shown | G38: as expected | H38: fail | I38: only fot otp validation message is shown
A39: AU-38 | B39: Auth - Set New Password | C39: Show or hide password (eye icon) | D39: Set New Password page is open | E39: 1. Click the eye icon on both password fields | F39: Password is shown and hidden correctly | G39: as expected | H39: Pass
A40: AU-39 | B40: Auth - Set New Password | C40: OTP cannot be reused | D40: Password was reset with an OTP | E40: 1. Use the same OTP again | F40: OTP is rejected | G40: as expected | H40: Pass
...

Sheet Auth Settings
A1: Setting | B1: Value (fill from developer) | C1: Seen in screenshots
A2: Wrong password attempts before account lock (N) | B2: Ask developer | C2: Not shown
A3: Account lock duration | B3: 10 minutes | C3: Yes: 'Try again in 10 minute(s)'
A4: Login rate limit (requests and time) | B4: Ask developer | C4: Not shown
A5: OTP length | B5: 6 digits | C5: Yes
A6: OTP validity time | B6: Ask developer | C6: Not shown
A7: OTP resend wait time | B7: About 60 seconds | C7: Yes: countdown seen at 58s
A8: OTP request limit (Forgot Password rate limit) | B8: Ask developer | C8: Message seen: 'Too many requests right now'
A9: Wrong OTP attempts allowed | B9: Ask developer | C9: Not shown
A10: Minimum password length | B10: 6 characters | C10: Yes
A11: Session idle timeout | B11: 30 minutes | C11: Told by team
A12: Shortened timeout available on test environment? | B12: Ask developer (saves waiting 30 minutes)

Sheet Bug Log
A1: Bug ID | B1: Module | C1: Test Case ID | D1: Language | E1: Actual Result (what you saw) | F1: Expected Result | G1: Severity | H1: Bug Status | I1: Reported By | J1: Remarks
A2: BUG-001 | B2: testimonial | C2: CR-006 | J2: not enough data
A3: BUG-002 | C3: cr-09 | J3: validation for image is only shown when all other validation has passed
A4: BUG-003 | B4: Screening Feedback | C4: cr-02 | J4: SPAN card description has issues
A5: BUG-004 | C5: CR-03 | J5: search for anxiety and depression is not possible, switches to other tab when search is done
A6: BUG-005 | C6: cr-06 | J6: no pagination
A7: BUG-006
A8: BUG-007 | B8: Suggestions | C8: CR-02 | J8: content in the cards needs to be adjusted
A9: BUG-008 | C9: lg-01 | J9: Not all cards content is in nepali and some heading are still in english
A10: BUG-009 | C10: lg-08 | J10: search in nepali doesn’t work, nepali character problem
A11: BUG-010
A12: BUG-011 | B12: Questionnaires | C12: CR-02 | J12: for SPAN Screening, one title is in nepali
A13: BUG-012 | C13: CR-03 | J13: Searching for only anxiety is possible, serch while on other tabs swithes the cards to anxiety.
A14: BUG-013 | C14: CR-10 | J14: No validation message is shown
A15: BUG-014 | C15: Cr-13 | J15: Some dropdoown shows the nepali content while in english mode
A16: BUG-015 | C16: CR-12 | J16: Can enter/have duplicate entries during edit option
A17: BUG-016 | C17: lg-01 | J17: Some content of YUWA 26 and above is in english
A18: BUG-017 | C18: lg-09 | J18: not intended, cant perform search in other tabs other than anxity/chinta | K18: Note: added a test card in anxiety tab, kindly delete it, has 2 test that has this test value.
A19: BUG-018
A20: BUG-019 | B20: Faqs | C20: CR-24 | J20: Cant see in the public site in english
A21: BUG-020 | C21: lg-07 | J21: Cant see in the public site in nepali
A22: BUG-021 | C22: lg-09
A23: BUG-022
A24: BUG-023 | B24: Aboutus | C24: cr01and cr 02 | J24: one card is in nepali and swasth mann category name is confused with mental health
A25: BUG-024 | C25: CR-03 | J25: search cant be done for Mental Health
A26: BUG-025 | C26: cr12 | J26: allows duplicate data entry
A27: BUG-026
A28: BUG-027 | B28: self care | C28: cr02 | J28: shows nepali content
A29: BUG-028 | C29: cr-06 | J29: no pagination
A30: BUG-029 | C30: cr-10 | J30: validation for title not present
A31: BUG-030 | B31: Video Categories
A32: BUG-031 | C32: lg-01 to lg05 and lg07 | D32: no nepali content | E32: no nepali content | F32: no nepali content | G32: no nepali content | H32: no nepali content | I32: no nepali content | J32: no nepali content
A33: BUG-032
A34: BUG-033
A35: BUG-034 | B35: other resources | C35: cr-search | J35: search can only be carried for the default title on load
A36: BUG-035 | C36: cr-12 | J36: allows duplicate entry
A37: BUG-036 | C37: lg-01 | J37: some content appears in nepali
A38: BUG-037 | C38: lg08 | J38: search can only be carried for the single category.
A39: BUG-038 | C39: lg09
A40: BUG-039
...

Sheet Issues to Verify
A1: # | B1: Module | C1: Issue seen in screenshots | D1: Related Test Case
A2: 1 | B2: FAQs | C2: Edit popup opened from an FAQ is titled 'Edit Emergency Contact' (field is FAQ). Wrong title | D2: CR-17
A3: 2 | B3: FAQs | C3: List order is not clearly by date (05 Aug, 27 Aug, 11 Oct 2023 mixed). Confirm the intended sort order | D3: CR-02
A4: 3 | B4: All modules | C4: 'Live Content' banner says changes reflect in the app immediately. Verify in the app | D4: CR-24
A5: 4 | B5: Authentication | C5: Login page Password field has no show/hide (eye) icon, but the Reset Password page has one. Confirm this is intended | D5: AU-01, AU-38
A6: 5 | B6: Authentication | C6: Forgot Password rate-limit message says 'try again in a little while' with no time, but login lock says 10 minutes. Confirm the wait time and message | D6: AU-23
A7: 6 | B7: Authentication | C7: Confirm whether resetting the password unlocks a locked account | D7: AU-26
A8: 7 | B8: Authentication | C8: Confirm the number of wrong attempts before lock, OTP validity and OTP limits, and fill them in the Auth Settings tab | D8: AU-09, AU-23, AU-32, AU-33
